Workbook

Sheet messy_sales
A1: order_id | B1: order_date | C1: customer_name | D1: country_code | E1: region | F1: customer_size | G1: revenue
A2: ORD-01001 | B2: 45572 | C2: Alpine Ski House | D2: DE | E2: EMEA | F2: SMB | G2: 306.58
A3: ORD-01002 | B3: not a date | C3: Nordwind Energie | D3: DE | E3: EMEA | F3: Mid-Market | G3: 4353.36
A4: ORD-01003 | B4: 45519 | C4: Tailspin Toys | D4: ca | E4: North America | F4: SMB
A5: ORD-01004 | B5: 45321 | C5: Delhi Textiles | D5: In | E5: APAC | F5: SMB | G5: 1685.44
A6: ORD-01005 | B6: 45771 | C6: Lion City Traders | D6: SG | E6: APAC | F6: Mid-Market | G6: 11996.33
A7: ORD-01006 | B7: 45674 | C7: Mumbai Fresh Foods | D7: in | E7: APAC | F7: SMB | G7: 2913.04
A8: ORD-01007 | B8: 45313 | C8: Proseware GmbH | D8: de | E8: EMEA | F8: Enterprise | G8: 35412.77
A9: ORD-01008 | B9: 45563 | C9: Blue Yonder Airlines | D9: Us | E9: North America | F9: Enterprise | G9: 20575.8
A10: ORD-01009 | B10: 45422 | C10: Coho Vineyard | D10: us | E10: North America | F10: SMB | G10: 2676.39
A11: ORD-01010 | B11: 45751 | C11: Sydney Harbour Goods | D11: Au | E11: APAC | F11: SMB | G11: 1684.85
A12: ORD-01011 | B12: 45463 | C12: Fabrikam Inc | D12: Us | E12: North America | F12: Mid-Market | G12: 8499.56
A13: ORD-01012 | B13: 45602 | C13: Litware Systems | D13: Gb | E13: EMEA | F13: Enterprise | G13: 23617.89
A14: ORD-01013 | B14: 45572 | C14: Wide World Importers | D14: GB | E14: EMEA | F14: Mid-Market | G14: 4262.97
A15: ORD-01014 | B15: 45702 | C15: Outback Supplies | D15: Au | E15: APAC | F15: Mid-Market | G15: 9752.79
A16: ORD-01015 | B16: 45527 | C16: Desert Trading LLC | D16: Ae | E16: EMEA | F16: Mid-Market | G16: 7788.27
... A28: ORD-01027 | B28: 45837 | C28: Contoso Ltd | D28: Us | E28: North America | F28: Enterprise | G28: 39528.52
A29: ORD-01028 | B29: 17/11/2024 | C29: Contoso Ltd | D29: us | E29: North America | F29: Enterprise | G29: 16152.37
A30: ORD-01029 | B30: 21/05/2024 | C30: Hanseatic Imports | D30: De | E30: EMEA | F30: SMB | G30: 2816.96
A31: ORD-01030 | B31: 45837 | C31: Contoso Ltd | D31: US | E31: North America | F31: Enterprise | G31: 37694.85
A32: ORD-01031 | B32: 45738 | C32: Gulf Logistics | D32: ae | E32: EMEA | F32: Enterprise
A33: ORD-01032 | B33: 45636 | C33: Emirates Retail Group | D33: AE | E33: EMEA | F33: Enterprise | G33: 27283.78
A34: ORD-01033 | B34: 45906 | C34: Coho Vineyard | D34: us | E34: North America | F34: SMB | G34: 2882.46
A35: ORD-01034 | B35: 45635 | C35: Nordwind Energie | D35: de | E35: EMEA | F35: Mid-Market | G35: 10142.51
A36: ORD-01035 | B36: 45548 | C36: Wide World Importers | D36: Gb | E36: EMEA | F36: Mid-Market | G36: 8416.68
A37: ORD-01036 | B37: 45526 | C37: Tata Consultancy Retail | D37: In | E37: APAC | F37: Enterprise | G37: 29237.12
A38: ORD-01037 | B38: 45710 | C38: Contoso Ltd | D38: Us | E38: North America | F38: Enterprise | G38: 23643.03
A39: ORD-01038 | B39: 45829 | C39: Pacific Northwest Co | D39: us | E39: North America | F39: Mid-Market | G39: 5004.12
A40: ORD-01039 | B40: 45725 | C40: Nordwind Energie | D40: De | E40: EMEA | F40: Mid-Market | G40: 8575.67
A41: ORD-01040 | B41: 45633 | C41: Sydney Harbour Goods | D41: Au | E41: APAC | F41: SMB | G41: 1951.7
A42: ORD-01041 | B42: 45744 | C42: Tailspin Toys | D42: CA | E42: North America | F42: SMB | G42: 2955.55
A43: ORD-01042 | B43: 45667 | C43: Adventure Works | D43: ca | E43: North America | F43: Mid-Market | G43: 7915.42
A44: ORD-01043 | B44: 45394 | C44: Great Barrier Retail | D44: AU | E44: APAC | F44: SMB | G44: 380.98
A45: ORD-01044 | B45: 27/10/2024 | C45: Emirates Retail Group | D45: Ae | E45: EMEA | F45: Enterprise | G45: 18161.61
A46: ORD-01045 | B46: 45525 | C46: Gulf Logistics | D46: Ae | E46: EMEA | F46: Enterprise | G46: 33648.31
A47: ORD-01046 | B47: 2025-02-31 | C47: Thames Valley Foods | D47: gb | E47: EMEA | F47: Mid-Market | G47: 9913.66
A48: ORD-01047 | B48: 45673 | C48: Hanseatic Imports | D48: de | E48: EMEA | F48: SMB | G48: 2741
A49: ORD-01048 | B49: 45605 | C49: Mumbai Fresh Foods | D49: In | E49: APAC | F49: SMB | G49: 740.04
A50: ORD-01049 | B50: 45803 | C50: Tailspin Toys | D50: CA | E50: North America | F50: SMB | G50: 2895.75
A51: ORD-01050 | B51: 45667 | C51: Pacific Northwest Co | D51: US | E51: North America | F51: Mid-Market | G51: 3453.29
...

Sheet Clean_Data
A1: Order ID | B1: Order Date | C1: Customer Name | D1: Country Code | E1: Region | F1: Customer Size | G1: Revenue
A2: =messy_sales!A2 -> ORD-01001 | B2: =IFERROR(DATEVALUE(messy_sales!B2), "Invalid Date") -> 45572 | C2: =TRIM(messy_sales!C2) -> Alpine Ski House | D2: =UPPER(TRIM(messy_sales!D2)) -> DE | E2: =messy_sales!E2 -> EMEA | F2: =messy_sales!F2 -> SMB | G2: =IF(messy_sales!G2="", "Missing" , messy_sales!G2) -> 306.58
A3: =messy_sales!A3 -> ORD-01002 | B3: =IFERROR(DATEVALUE(messy_sales!B3), "Invalid Date") -> Invalid Date | C3: =TRIM(messy_sales!C3) -> Nordwind Energie | D3: =UPPER(TRIM(messy_sales!D3)) -> DE | E3: =messy_sales!E3 -> EMEA | F3: =messy_sales!F3 -> Mid-Market | G3: =IF(messy_sales!G3="", "Missing" , messy_sales!G3) -> 4353.36
A4: =messy_sales!A4 -> ORD-01003 | B4: =IFERROR(DATEVALUE(messy_sales!B4), "Invalid Date") -> 45519 | C4: =TRIM(messy_sales!C4) -> Tailspin Toys | D4: =UPPER(TRIM(messy_sales!D4)) -> CA | E4: =messy_sales!E4 -> North America | F4: =messy_sales!F4 -> SMB | G4: =IF(messy_sales!G4="", "Missing" , messy_sales!G4) -> Missing
A5: =messy_sales!A5 -> ORD-01004 | B5: =IFERROR(DATEVALUE(messy_sales!B5), "Invalid Date") -> 45321 | C5: =TRIM(messy_sales!C5) -> Delhi Textiles | D5: =UPPER(TRIM(messy_sales!D5)) -> IN | E5: =messy_sales!E5 -> APAC | F5: =messy_sales!F5 -> SMB | G5: =IF(messy_sales!G5="", "Missing" , messy_sales!G5) -> 1685.44
A6: =messy_sales!A6 -> ORD-01005 | B6: =IFERROR(DATEVALUE(messy_sales!B6), "Invalid Date") -> 45771 | C6: =TRIM(messy_sales!C6) -> Lion City Traders | D6: =UPPER(TRIM(messy_sales!D6)) -> SG | E6: =messy_sales!E6 -> APAC | F6: =messy_sales!F6 -> Mid-Market | G6: =IF(messy_sales!G6="", "Missing" , messy_sales!G6) -> 11996.33
A7: =messy_sales!A7 -> ORD-01006 | B7: =IFERROR(DATEVALUE(messy_sales!B7), "Invalid Date") -> 45674 | C7: =TRIM(messy_sales!C7) -> Mumbai Fresh Foods | D7: =UPPER(TRIM(messy_sales!D7)) -> IN | E7: =messy_sales!E7 -> APAC | F7: =messy_sales!F7 -> SMB | G7: =IF(messy_sales!G7="", "Missing" , messy_sales!G7) -> 2913.04
A8: =messy_sales!A8 -> ORD-01007 | B8: =IFERROR(DATEVALUE(messy_sales!B8), "Invalid Date") -> 45313 | C8: =TRIM(messy_sales!C8) -> Proseware GmbH | D8: =UPPER(TRIM(messy_sales!D8)) -> DE | E8: =messy_sales!E8 -> EMEA | F8: =messy_sales!F8 -> Enterprise | G8: =IF(messy_sales!G8="", "Missing" , messy_sales!G8) -> 35412.77
A9: =messy_sales!A9 -> ORD-01008 | B9: =IFERROR(DATEVALUE(messy_sales!B9), "Invalid Date") -> 45563 | C9: =TRIM(messy_sales!C9) -> Blue Yonder Airlines | D9: =UPPER(TRIM(messy_sales!D9)) -> US | E9: =messy_sales!E9 -> North America | F9: =messy_sales!F9 -> Enterprise | G9: =IF(messy_sales!G9="", "Missing" , messy_sales!G9) -> 20575.8
A10: =messy_sales!A10 -> ORD-01009 | B10: =IFERROR(DATEVALUE(messy_sales!B10), "Invalid Date") -> 45422 | C10: =TRIM(messy_sales!C10) -> Coho Vineyard | D10: =UPPER(TRIM(messy_sales!D10)) -> US | E10: =messy_sales!E10 -> North America | F10: =messy_sales!F10 -> SMB | G10: =IF(messy_sales!G10="", "Missing" , messy_sales!G10) -> 2676.39
A11: =messy_sales!A11 -> ORD-01010 | B11: =IFERROR(DATEVALUE(messy_sales!B11), "Invalid Date") -> 45751 | C11: =TRIM(messy_sales!C11) -> Sydney Harbour Goods | D11: =UPPER(TRIM(messy_sales!D11)) -> AU | E11: =messy_sales!E11 -> APAC | F11: =messy_sales!F11 -> SMB | G11: =IF(messy_sales!G11="", "Missing" , messy_sales!G11) -> 1684.85
A12: =messy_sales!A12 -> ORD-01011 | B12: =IFERROR(DATEVALUE(messy_sales!B12), "Invalid Date") -> 45463 | C12: =TRIM(messy_sales!C12) -> Fabrikam Inc | D12: =UPPER(TRIM(messy_sales!D12)) -> US | E12: =messy_sales!E12 -> North America | F12: =messy_sales!F12 -> Mid-Market | G12: =IF(messy_sales!G12="", "Missing" , messy_sales!G12) -> 8499.56
A13: =messy_sales!A13 -> ORD-01012 | B13: =IFERROR(DATEVALUE(messy_sales!B13), "Invalid Date") -> 45602 | C13: =TRIM(messy_sales!C13) -> Litware Systems | D13: =UPPER(TRIM(messy_sales!D13)) -> GB | E13: =messy_sales!E13 -> EMEA | F13: =messy_sales!F13 -> Enterprise | G13: =IF(messy_sales!G13="", "Missing" , messy_sales!G13) -> 23617.89
... A441: =messy_sales!A441 -> ORD-01440 | B441: =IFERROR(DATEVALUE(messy_sales!B441), "Invalid Date") -> 45321 | C441: =TRIM(messy_sales!C441) -> Tata Consultancy Retail | D441: =UPPER(TRIM(messy_sales!D441)) -> IN | E441: =messy_sales!E441 -> APAC | F441: =messy_sales!F441 -> Enterprise | G441: =IF(messy_sales!G441="", "Missing" , messy_sales!G441) -> 21247.09

Sheet Pivot_Table
A23: Revenue associated with invalid dates: $342,174.67 across 22 records.

Sheet Dashboard
A1: Sales Operation Dashboard
A4: Total Revenue
A5: =SUM(Clean_Data!G2:G441) -> 4864532
A6: Total Orders
A7: =COUNTA(Clean_Data!C2:C441) -> 440
A8: Customers
A9: {=COUNTA(UNIQUE(Clean_Data!C2:C441))} -> 30
A10: Missing Revenue
A11: =COUNTIF(Clean_Data!G2:G441,"Missing") -> 7
